Workbook

Sheet Weekly Timeline
A1: Documented actions and policies of the second Trump administration reported as harmful by major news outlets, courts, and government data — Jan 20, 2025 through Jul 8, 2026. One row per event; weeks with multiple events have multiple rows; quiet weeks are skipped. This compiles critical coverage as requested; the administration and its supporters dispute many of these characterizations. See the Sources tab (matching Ref #) and verify details independently before citing.
A2: Week Of (Mon) | B2: Date(s) | C2: Category | D2: Event / Action | E2: Documented Impact / Why Critics Object | F2: Source Ref
A3: Jan 19, 2025 | B3: Jan 20 | C3: Democracy & Rule of Law | D3: Pardoned ~1,500 Jan. 6 defendants, including those convicted of violently assaulting police officers; commuted sentences of Proud Boys/Oath Keepers leaders | E3: Erased accountability for the Capitol attack; condemned by police unions and prosecutors as endorsing political violence | F3: 1
A4: Jan 19, 2025 | B4: Jan 20 | C4: Immigration | D4: Signed executive order attempting to end birthright citizenship for children of undocumented and temporary-status parents | E4: Directly contradicted the 14th Amendment; every reviewing judge blocked it (one called it 'blatantly unconstitutional'); would have stripped citizenship from ~255,000 newborns/year (Migration Policy Institute) | F4: 2
A5: Jan 19, 2025 | B5: Jan 20 | C5: LGBTQ+ Rights | D5: Executive order declaring the federal government recognizes only two sexes, rolling back protections for transgender people; halted new X-marker passports | E5: Removed federal recognition of trans and nonbinary Americans; used to strip protections across agencies, prisons, and documents | F5: 3
A6: Jan 19, 2025 | B6: Jan 20 | C6: Civil Rights & Minorities | D6: Ordered termination of all federal DEI programs; DEI staff placed on leave then fired; later revoked LBJ-era EO 11246 barring discrimination by federal contractors | E6: Dismantled decades-old civil-rights enforcement infrastructure; chilled diversity programs across government and private sector | F6: 4
A7: Jan 19, 2025 | B7: Jan 20 | C7: Environment & Science | D7: Withdrew the U.S. from the Paris Climate Agreement (again) and from the World Health Organization | E7: Isolated the U.S. from global climate and health cooperation; WHO exit cut ~18% of its budget, weakening pandemic preparedness | F7: 5
A8: Jan 19, 2025 | B8: Jan 20 | C8: Executive Power | D8: Reinstated 'Schedule F' (renamed Schedule Policy/Career), stripping civil-service protections from tens of thousands of federal employees; loyalty screening of hires | E8: Enabled replacement of nonpartisan civil servants with political loyalists — a core 'unitary executive' power expansion | F8: 6
A9: Jan 19, 2025 | B9: Jan 24-25 | C9: Democracy & Rule of Law | D9: Fired at least 17 inspectors general in a late-night purge without the legally required 30-day notice to Congress | E9: Removed independent watchdogs overseeing waste, fraud and abuse, in apparent violation of the Inspector General Act | F9: 7
A10: Jan 26, 2025 | B10: Jan 27-29 | C10: Executive Power | D10: OMB memo froze virtually all federal grants and loans; Medicaid portals went down in all 50 states before the memo was rescinded amid chaos and court orders | E10: Attempted unilateral impoundment of congressionally appropriated funds — an unconstitutional power grab per multiple courts; disrupted services nationwide | F10: 8
A11: Jan 26, 2025 | B11: Jan 29-30 | C11: Civil Rights & Minorities | D11: After the deadly DCA midair collision (67 dead), blamed DEI hiring at the FAA without evidence, from the White House podium | E11: Baselessly scapegoated diversity programs and disabled workers during a national tragedy; contradicted by investigators | F11: 9
A12: Jan 26, 2025 | B12: Jan 28 | C12: Federal Workforce | D12: OPM 'Fork in the Road' email pushed ~2 million federal workers toward 'deferred resignation' buyouts amid threats of mass layoffs | E12: Destabilized the civil service; unions sued; many who accepted were later left in limbo | F12: 10
A13: Jan 26, 2025 | B13: Jan 29 | C13: Immigration | D13: Ordered DHS to prepare Guantanamo Bay to detain up to 30,000 migrants | E13: Extended offshore detention infrastructure historically criticized for rights abuses to civil immigration detainees | F13: 11
A14: Feb 2, 2025 | B14: Feb 3-7 | C14: Executive Power | D14: Elon Musk's DOGE gained access to the Treasury federal payment system and sensitive data across agencies; career officials who resisted were pushed out | E14: Unvetted political operatives obtained Americans' sensitive financial data; courts later restricted access; raised massive conflict-of-interest concerns | F14: 12
... A158: Jul 6, 2026 | B158: Jul 7 | C158: Executive Power | D158: Open-ended National Guard deployment in DC continued through the July 4 semiquincentennial; civil-rights groups asked Michigan's governor to withdraw troops, saying 'there is nothing normal' about Trump's use of the Guard in the capital | E158: Nearly 11 months of military presence in Washington with no end date | F158: 156
A159: Jul 13, 2026 | B159: Jul 13 | F159: 157
A160: Jul 13, 2026 | B160: Jul 14 | F160: 158
A161: Aug 17, 2026 | B161: Aug 17 | F161: 159
A162: Aug 17, 2026 | B162: Aug 18 | F162: 160
A163: Aug 17, 2026 | B163: Aug 18 | F163: 161
A164: Aug 17, 2026 | B164: Aug 18 | F164: 162
A165: Aug 17, 2026 | B165: Aug 19 | F165: 163
A166: Aug 17, 2026 | B166: Aug 20 | F166: 164
A167: Aug 17, 2026 | B167: Aug 20 | F167: 165
A168: Aug 17, 2026 | B168: Aug 20 | F168: 166
A169: Aug 17, 2026 | B169: Aug 21 | F169: 167
A170: Aug 17, 2026 | B170: Aug 21 | F170: 168
... A213: Jul 13, 2026 | B213: Jul 17 | F213: 211
A214: Aug 24, 2026 | B214: Aug 26 | C214: Courts & SCOTUS | F214: 212
A215: Aug 24, 2026 | B215: Aug 27 | C215: Foreign Policy & Aid | F215: 213
A216: Aug 24, 2026 | B216: Aug 27 | C216: Civil Liberties | F216: 214
A217: Aug 24, 2026 | B217: Aug 27 | C217: Foreign Policy & Aid | F217: 215
A218: Aug 24, 2026 | B218: Aug 27 | C218: Executive Power | F218: 216
A219: Aug 24, 2026 | B219: Aug 28 | C219: Economy & Tariffs | F219: 217
A220: Aug 24, 2026 | B220: Aug 28 | C220: Executive Power | F220: 218
A221: Aug 24, 2026 | B221: Aug 28 | C221: Democracy & Rule of Law | F221: 219
A222: Aug 24, 2026 | B222: Aug 28 | F222: 220
A223: Aug 31, 2026 | B223: Sep 3 | C223: Democracy & Rule of Law | F223: 221
A224: Aug 31, 2026 | B224: Sep 3 | C224: Infrastructure and History | F224: 222
A225: Aug 31, 2026 | B225: Sep 4 | C225: Democracy & Rule of Law | F225: 223
...

Sheet Sources
A1: Ref # matches the Source Ref column on the Weekly Timeline tab. URLs are provided where verified via current web results (mostly 2026 items). For 2025 items, outlet names and dates are given; searching the description text will locate the original coverage. Per your request the mix emphasizes CNN, Politico, MSNBC/MS NOW, NBC and independent outlets, alongside AP, Reuters, Guardian, NPR, CBS, ABC and court documents.
A2: Ref # | B2: Outlet(s) | C2: Story / Description | D2: URL (if verified) | E2: Date
A3: 1 | B3: AP News; Politico; NBC News | C3: Coverage of Jan. 6 blanket pardons on Inauguration Day | E3: Jan 20, 2025
A4: 2 | B4: Reuters; NPR; CNN | C4: Birthright citizenship EO and immediate court blocks | E4: Jan 20-23, 2025
A5: 3 | B5: NBC News; The 19th; CNN | C5: 'Two sexes' executive order coverage | E5: Jan 20, 2025
A6: 4 | B6: AP News; Washington Post | C6: Federal DEI shutdown and EO 11246 revocation | E6: Jan 20-22, 2025
A7: 5 | B7: Reuters; NPR | C7: Paris Agreement and WHO withdrawal orders | E7: Jan 20, 2025
A8: 6 | B8: Government Executive; AP News | C8: Schedule F revival coverage | E8: Jan 20, 2025
A9: 7 | B9: AP News; Reuters | C9: Mass IG firings without statutory notice | E9: Jan 24-25, 2025
A10: 8 | B10: NBC News; Politico; NPR | C10: OMB funding freeze memo chaos | E10: Jan 27-29, 2025
A11: 9 | B11: AP News; PBS | C11: Trump blames DEI for DCA crash | E11: Jan 30, 2025
A12: 10 | B12: Washington Post; Reuters | C12: Deferred resignation buyout offer | E12: Jan 28, 2025
A13: 11 | B13: AP News; NYT | C13: Guantanamo migrant detention order | E13: Jan 29, 2025
A14: 12 | B14: Politico; NYT; Wired | C14: DOGE Treasury payment system access | E14: Feb 2025
... A81: 79 | B81: AP News; Reuters | C81: Immigration halt announcement | E81: Nov 26-28, 2025
A82: 80 | B82: The Hill; American Prospect | C82: SCOTUS Chicago Guard ruling | D82: https://prospect.org/2026/01/06/supreme-court-trump-national-guard/ | E82: late Dec 2025
A83: 81 | B83: The Hill; Democracy Docket | C83: Guard pullback + Insurrection Act threat | D83: https://thehill.com/regulation/court-battles/5668540-federal-forces-pullback-cities/ | E83: Dec 31, 2025
A84: 82 | B84: BBC News | C84: US captures Maduro after strikes on Venezuelan capital Caracas | D84: https://www.bbc.co.uk/news/articles/cpdyvn176lzo | E84: Jan 3, 2026
A85: 83 | B85: PBS News / AP | C85: Trump administration cuts number of vaccines it recommends for every child | D85: https://www.pbs.org/newshour/health/trump-administration-cuts-number-of-vaccines-it-recommends-for-every-child | E85: Jan 5, 2026
A86: 84 | B86: The Hill | C86: White House unveils Jan. 6 webpage saying Democrats 'staged the real insurrection' | D86: https://thehill.com/homenews/administration/5675182-trump-launches-jan6-website/ | E86: Jan 6, 2026
A87: 85 | B87: Capitol News Illinois | C87: Trump freezes $10B in social service, child care funding for 5 blue states | D87: https://capitolnewsillinois.com/news/trump-freezes-10b-in-social-service-child-care-funding-for-illinois-4-other-blue-states/ | E87: Jan 7, 2026
A88: 86 | B88: The Guardian | C88: Woman in Minnesota fatally shot by ICE agent during raid, video shows | D88: https://www.theguardian.com/us-news/2026/jan/07/minneapolis-shooting-immigration-crackdown | E88: Jan 7, 2026
A89: 87 | B89: White House / Federal Register | C89: EO: Withdrawing the United States from International Organizations, Conventions, and Treaties | D89: https://www.whitehouse.gov/presidential-actions/2026/01/withdrawing-the-united-states-from-international-organizations-conventions-and-treaties-that-are-contrary-to-the-interests-of-the-united-states/ | E89: Jan 7, 2026
A90: 88 | B90: Politico | C90: Day after Minneapolis shooting, Noem ordered new restriction on congressional oversight | D90: https://www.politico.com/news/2026/01/10/minnesota-democrats-ice-00721211 | E90: Jan 10, 2026
A91: 89 | B91: Bloomberg | C91: US Agriculture Secretary Suspends Benefit Funds to Minnesota | D91: https://www.bloomberg.com/news/articles/2026-01-10/us-agriculture-secretary-suspends-benefit-funds-to-minnesota | E91: Jan 10, 2026
A92: 90 | B92: The Guardian | C92: Musk's AI tool Grok will be integrated into Pentagon networks, Hegseth says | D92: https://www.theguardian.com/technology/2026/jan/13/elon-musk-grok-hegseth-military-pentagon | E92: Jan 13, 2026
A93: 91 | B93: KOMO / Sinclair | C93: DHS Secretary Kristi Noem ends Temporary Protected Status for Somali nationals | D93: https://komonews.com/news/nation-world/dhs-secretary-kristi-noem-ends-temporary-protected-status-for-somali-nationals-nick-shirley-minnesota-minneapolis | E93: Jan 13, 2026
... A156: 154 | B156: CNN | C156: Supreme Court lets states ban transgender athletes from girls' sports; campaign finance cap lifted | D156: https://www.cnn.com/2026/06/30/politics/live-news/supreme-court-cases-news | E156: Jun 30, 2026
A157: 155 | B157: AP News (via Britannica news feed) | C157: Lawsuit says US illegally shared confidential information on Iranian asylum seekers with Iran | E157: Jul 7, 2026
A158: 156 | B158: Boston Globe / AP live coverage | C158: Trump presidency live updates — DC Guard deployment concerns | D158: https://www.bostonglobe.com/2026/07/07/nation/trump-presidency-live-updates/ | E158: Jul 7, 2026
A159: 157 | B159: NBC News | C159: On the same day, a Florida airport and a Tennessee bridge are renamed after Trump | D159: https://www.nbcnews.com/politics/donald-trump/palm-beach-international-airport-tennessee-bridge-renamed-rcna353784 | E159: Jul 10, 2026
A160: 158 | B160: The Guardian | C160: Trump restarts war with Iran and plays nice(ish) with Nato | Politics Weekly America | D160: https://www.theguardian.com/politics/video/2026/jul/10/trump-restarts-war-with-iran-and-plays-niceish-with-nato-politics-weekly-america | E160: Jul 10, 2026
A161: 159 | B161: ABC News | C161: Crews draining the Lincoln Memorial Reflecting Pool again as part of troubled revamp | D161: https://abcnews.com/Politics/wireStory/crews-draining-lincoln-memorial-reflecting-pool-part-trumps-134656303 | E161: Jul 10, 2026
A162: 160 | B162: PBS NewsHour | C162: Trump fires election commission members in latest attempt to control voting process | D162: https://www.pbs.org/newshour/show/trump-fires-election-commission-members-in-latest-attempt-to-control-voting-process | E162: Jul 10, 2026
A163: 161 | B163: PBS NewsHour | C163: Federal officials refusing to release name of ICE officer who fatally shot Lorenzo Salgado Araujo | D163: https://www.pbs.org/newshour/politics/federal-officials-refusing-to-release-name-of-ice-officer-who-fatally-shot-lorenzo-salgado-araujo | E163: Jul 10, 2026
A164: 162 | B164: NPR | C164: Justice Department subpoenas New York Times reporters over Air Force One reporting | D164: https://www.npr.org/2026/07/11/g-s1-133160/justice-department-subpoenas-new-york-times-reporters-over-air-force-one-reporting | E164: Jul 11, 2026
A165: 163 | B165: NBC News | C165: Judge tosses remaining Jan. 6 Proud Boys convictions after DOJ request | D165: https://www.nbcnews.com/politics/justice-department/judge-grants-doj-request-toss-remaining-jan-6-convictions-proud-boys-rcna385952 | E165: Jul 11, 2026
A166: 157 | B166: PBS NewsHour | C166: ICE shot and killed a Colombian man in Maine. This is the 2nd time in a week the agency used deadly force | D166: https://www.pbs.org/newshour/nation/ice-shot-and-killed-a-colombian-man-in-maine-this-is-the-2nd-time-in-a-week-the-agency-used-deadly-force | E166: Jul 13, 2026
A167: 158 | B167: CBS News | C167: Military action against Iran formally restarted last week, Trump told lawmakers | D167: https://www.cbsnews.com/news/iran-military-action-formally-restarted-trump-lawmakers-war-powers/ | E167: Jul 14, 2026
A168: 159 | B168: NBC News | C168: Trump ‘doesn’t have a plan’ on Iran: Voters in key Pennsylvania district upset with handling of war | D168: https://www.nbcnews.com/meet-the-press/video/trump-doesn-t-have-a-plan-on-iran-voters-in-key-pennsylvania-district-upset-with-handling-of-war-268422725765 | E168: Aug 17, 2026
...

Sheet Summary
A1: Entries by category (live COUNTIF formulas against the Weekly Timeline tab)
A2: Category | B2: Entries
A3: Civil Liberties | B3: =COUNTIF('Weekly Timeline'!C:C,A3) -> 3
A4: Civil Rights & Minorities | B4: =COUNTIF('Weekly Timeline'!C:C,A4) -> 16
A5: Courts & SCOTUS | B5: =COUNTIF('Weekly Timeline'!C:C,A5) -> 11
A6: Dangerous Rhetoric | B6: =COUNTIF('Weekly Timeline'!C:C,A6) -> 3
A7: Democracy & Rule of Law | B7: =COUNTIF('Weekly Timeline'!C:C,A7) -> 37
A8: Economy & Tariffs | B8: =COUNTIF('Weekly Timeline'!C:C,A8) -> 14
A9: Education | B9: =COUNTIF('Weekly Timeline'!C:C,A9) -> 5
A10: Elections | B10: =COUNTIF('Weekly Timeline'!C:C,A10) -> 7
A11: Environment & Science | B11: =COUNTIF('Weekly Timeline'!C:C,A11) -> 7
A12: Executive Power | B12: =COUNTIF('Weekly Timeline'!C:C,A12) -> 38
A13: Federal Workforce | B13: =COUNTIF('Weekly Timeline'!C:C,A13) -> 3
A14: Foreign Policy & Aid | B14: =COUNTIF('Weekly Timeline'!C:C,A14) -> 21
... A24: Women's Rights / LGBTQ+ | B24: =COUNTIF('Weekly Timeline'!C:C,A24) -> 1
A25: Total entries | B25: =SUM(B3:B24) -> 223
